#VRML_SIM R2025a utf8

EXTERNPROTO "https://raw.githubusercontent.com/cyberbotics/webots/R2023b/projects/objects/backgrounds/protos/TexturedBackground.proto"
EXTERNPROTO "https://raw.githubusercontent.com/cyberbotics/webots/R2023b/projects/objects/backgrounds/protos/TexturedBackgroundLight.proto"

WorldInfo {
  basicTimeStep 16
  physicsDisableTime 0.5
}
Viewpoint {
  orientation -0.026611192142101142 0.019581252382721116 0.9994540604789699 1.8648382396304588
  position 1.920558517958081 -6.030554416062278 0.8101016671363437
}
TexturedBackground {
  texture "dawn_cloudy_empty"
}
TexturedBackgroundLight {
}
Shape {
  appearance PBRAppearance {
    baseColorMap ImageTexture {
      url [
        "piso.png"
      ]
    }
    roughness 0.8
    metalness 0.2
  }
  geometry Plane {
  }
}
Solid {
  translation 1.8499157947929374e-22 1.146537425507136e-19 -0.14794491028173776
  rotation 1 0 0 0
  children [
    Shape {
      appearance PBRAppearance {
        baseColorMap ImageTexture {
          url [
            "piso.png"
          ]
        }
        roughness 0.3
        metalness 0.7
      }
      geometry Box {
        size 100 0.3 0.05
      }
    }
  ]
  name "pista_deslizamiento"
  linearVelocity -6.451367309515557e-27 -6.869579148743197e-21 -0.00016093452178835626
  angularVelocity -9.832375154302014e-18 6.519256392494257e-19 1.3570948376840402e-23
}
Robot {
  translation 2.723364437366475e-07 5.749980345557833e-13 0.004568340372973021
  rotation -4.205626108565746e-06 0.9999999999906858 -9.700011478911355e-07 5.4453835389952996e-05
  children [
    GPS {
      name "gps_carro"
    }
    InertialUnit {
      name "inertial_carro"
    }
    SliderJoint {
      jointParameters JointParameters {
        position 1.1495396240748278e-07
        axis 1 0 0
        minStop -500
        maxStop 500
        dampingConstant 0.02
        staticFriction 0.005
      }
      device [
        LinearMotor {
          name "carro_motor"
          maxVelocity 5
          minPosition -500
          maxPosition 500
          maxForce 300
        }
        PositionSensor {
          name "carro_sensor"
        }
      ]
      endPoint Solid {
        translation 1.1495396240748278e-07 0 0.05
        children [
          Pose {
            translation 0 0 0.025
            children [
              Shape {
                appearance PBRAppearance {
                  baseColor 0.25 0.88 0.82
                  roughness 0.8
                  metalness 0.2
                }
                geometry Box {
                  size 0.5 0.45 0.1
                }
              }
            ]
          }
          HingeJoint {
            jointParameters HingeJointParameters {
              position -0.0006516575748034331
              axis 0 1 0
              anchor 0 0 0.05
              dampingConstant 0.01
            }
            device [
              PositionSensor {
                name "sensor_pendulo"
              }
            ]
            endPoint Solid {
              translation 0 0 0.05
              rotation 0 -0.9999999999999999 0 0.0006516575746712953
              children [
                Pose {
                  translation 0 -0.24 0.25
                  children [
                    Shape {
                      appearance PBRAppearance {
                        baseColor 0.5 0 0.8
                        roughness 0.9
                        metalness 0.1
                      }
                      geometry Cylinder {
                        height 0.5
                        radius 0.015
                      }
                    }
                  ]
                }
                Pose {
                  translation 0 -0.24 0.5
                  children [
                    Shape {
                      appearance PBRAppearance {
                        baseColor 0.5 0 0.8
                        roughness 0.5
                        metalness 0.3
                      }
                      geometry Sphere {
                        radius 0.045
                      }
                    }
                  ]
                }
              ]
              name "pendulo_solid"
              boundingObject Group {
                children [
                  Pose {
                    translation 0 0 0.25
                    children [
                      Cylinder {
                        height 0.5
                        radius 0.008
                      }
                    ]
                  }
                  Pose {
                    translation 0 0 0.5
                    children [
                      Sphere {
                        radius 0.045
                      }
                    ]
                  }
                ]
              }
              physics Physics {
                density -1
                mass 0.4
                centerOfMass [
                  0 0 0.4
                ]
                inertiaMatrix [
                  0.01 0.01 0.001
                  0 0 0
                ]
              }
              linearVelocity -8.045444934154193e-05 4.238148092043116e-15 -4.793127640567718e-08
              angularVelocity -1.0627092078396766e-14 -0.00020121715325500212 4.608153483027101e-14
            }
          }
        ]
        name "carro_solid"
        contactMaterial "carro_material"
        boundingObject Box {
          size 0.3 0.15 0.05
        }
        physics Physics {
          density -1
          mass 1.8
          centerOfMass [
            0 0 0
          ]
          inertiaMatrix [
            0.02 0.01 0.02
            0 0 0
          ]
          damping Damping {
            linear 0.1
            angular 0.5
          }
        }
        linearVelocity 3.181199538588229e-08 -1.680369141320445e-18 -1.0868984476912057e-12
        angularVelocity 1.3905513957840994e-21 2.5718430642018305e-11 -6.160578946962561e-20
      }
    }
  ]
  name "pendulo_robot"
  contactMaterial "carro_material"
  controller "pendulo_controller_2"
}
