#VRML_SIM R2025a utf8

EXTERNPROTO "https://raw.githubusercontent.com/cyberbotics/webots/R2023b/projects/objects/backgrounds/protos/TexturedBackground.proto"
EXTERNPROTO "https://raw.githubusercontent.com/cyberbotics/webots/R2023b/projects/objects/backgrounds/protos/TexturedBackgroundLight.proto"

WorldInfo {
  basicTimeStep 16
  physicsDisableTime 0.5
}
Viewpoint {
  orientation -0.1777830340547753 0.13372328056495986 0.9749416787876204 1.87483380026055
  position 1.2350747598194132 -4.769155711485903 1.927430342280057
}
TexturedBackground {
  texture "dawn_cloudy_empty"
}
TexturedBackgroundLight {
}
Shape {
  appearance PBRAppearance {
    baseColorMap ImageTexture {
      url [
        "piso.png"
      ]
    }
    roughness 0.8
    metalness 0.2
  }
  geometry Plane {
  }
}
Solid {
  translation 1.8502450725804214e-22 1.4971607452589977e-19 -0.1471235004825274
  rotation -0.99943068614015 0.033133117823633707 0.006363969257799828 3.148152336134892e-19
  children [
    Shape {
      appearance PBRAppearance {
            baseColorMap ImageTexture {
          url [
            "piso.png"
          ]
        }
        roughness 0.3
        metalness 0.7
      }
      geometry Box {
        size 100 0.3 0.05
      }
    }
  ]
  name "pista_deslizamiento"
  linearVelocity -6.451367309515557e-27 -6.869579148743197e-21 -0.00016093452178835626
  angularVelocity -9.832375154302014e-18 6.519256392494257e-19 1.3570948376840402e-23
}
Robot {
  translation 2.723364437366475e-07 5.749980345557833e-13 0.004568340372973021
  rotation -4.205626108565746e-06 0.9999999999906858 -9.700011478911355e-07 5.4453835389952996e-05
  children [
    GPS {
      name "gps_carro"
    }
    InertialUnit {
      name "inertial_carro"
    }
    SliderJoint {
      jointParameters JointParameters {
        position 6.9993998394344464e-09
        axis 1 0 0
        minStop -500
        maxStop 500
        dampingConstant 0.02
        staticFriction 0.005
      }
      device [
        LinearMotor {
          name "carro_motor"
          maxVelocity 5
          minPosition -500
          maxPosition 500
          maxForce 300
        }
        PositionSensor {
          name "carro_sensor"
        }
      ]
      endPoint Solid {
        translation 6.9993998394344464e-09 0 0.05
        children [
          Pose {
            translation 0 0 0.025
            children [
              Shape {
                appearance PBRAppearance {
                  baseColor 0.25 0.88 0.82
                  roughness 0.8
                  metalness 0.2
                }
                geometry Box {
                  size 0.5 0.45 0.1
                }
              }
            ]
          }

          HingeJoint {
            jointParameters HingeJointParameters {
              position -7.946509475952562e-05
              axis 0 1 0
              anchor 0 0 0.05
              dampingConstant 0.01
            }
            device [
              PositionSensor {
                name "sensor_pendulo"
              }
            ]
            endPoint Solid {
              translation 0 0 0.05
              rotation 0 -1 0 7.946509706341491e-05
              children [
                Pose {
                  translation 0 -0.24 0.25
                  children [
                    Shape {
                      appearance PBRAppearance {
                        baseColor 0.5 0 0.8
                        roughness 0.9
                        metalness 0.1
                      }
                      geometry Cylinder {
                        height 0.5
                        radius 0.015
                      }
                    }
                  ]
                }
                Pose {
                  translation 0 -0.24 0.5
                  children [
                    Shape {
                      appearance PBRAppearance {
                        baseColor 0.5 0 0.8
                        roughness 0.5
                        metalness 0.3
                      }
                      geometry Sphere {
                        radius 0.045
                      }
                    }
                  ]
                }
              ]
              name "pendulo_solid"
              boundingObject Group {
                children [
                  Pose {
                    translation 0 0 0.25
                    children [
                      Cylinder {
                        height 0.5
                        radius 0.008
                      }
                    ]
                  }
                  Pose {
                    translation 0 0 0.5
                    children [
                      Sphere {
                        radius 0.045
                      }
                    ]
                  }
                ]
              }
              physics Physics {
                density -1
                mass 0.4
                centerOfMass [
                  0 0 0.4
                ]
                inertiaMatrix [
                  0.01 0.01 0.001
                  0 0 0
                ]
              }
              linearVelocity -1.9871324788009957e-06 2.8321591653334376e-11 -7.783414446294046e-10
              angularVelocity -5.700817868210471e-11 -2.803805615593676e-05 4.096965164624061e-11
            }
          }
        ]
        name "carro_solid"
        contactMaterial "carro_material"
        boundingObject Box {
          size 0.3 0.15 0.05
        }
        physics Physics {
          density -1
          mass 1.8
          centerOfMass [
            0 0 0
          ]
          inertiaMatrix [
            0.02 0.01 0.02
            0 0 0
          ]
          damping Damping {
            linear 0.1
            angular 0.5
          }
        }
        linearVelocity 4.830545316376855e-06 2.6644165935100388e-12 -2.6391097969496386e-10
        angularVelocity -5.637348352553832e-11 8.681897193521346e-05 4.0491696144420284e-11
      }
    }
  ]
  name "pendulo_robot"
  contactMaterial "carro_material"
  controller "pendulo_controller_2"
}