#VRML_SIM R2025a utf8

EXTERNPROTO "https://raw.githubusercontent.com/cyberbotics/webots/R2025a/projects/objects/backgrounds/protos/TexturedBackground.proto"
EXTERNPROTO "https://raw.githubusercontent.com/cyberbotics/webots/R2025a/projects/objects/backgrounds/protos/TexturedBackgroundLight.proto"
EXTERNPROTO "https://raw.githubusercontent.com/cyberbotics/webots/R2025a/projects/objects/floors/protos/Floor.proto"
EXTERNPROTO "https://raw.githubusercontent.com/cyberbotics/webots/R2025a/projects/objects/floors/protos/RectangleArena.proto"

WorldInfo {
  basicTimeStep 16
}
Viewpoint {
  orientation 0.1386211257253888 0.33986488009965554 -0.9302021537157784 0.8267722213932307
  position -1.122836743488534 1.007843903607551 0.854237392377147
  description "Vista principal"
}
TexturedBackground {
}
TexturedBackgroundLight {
}
DirectionalLight {
  color 1 1 0.95
  direction -0.3 -1 -0.4
  intensity 0.9
}
Floor {
  appearance PBRAppearance {
    baseColorMap ImageTexture {
      url [
        "webots://projects/default/worlds/textures/wood.jpg"
      ]
    }
    roughness 0.5
    metalness 0
  }
}
RectangleArena {
  floorSize 5 5
  floorAppearance PBRAppearance {
    baseColorMap ImageTexture {
      url [
        "webots://projects/default/worlds/textures/rubber.jpg"
      ]
    }
  }
}
Solid {
  translation 0 0.01 0
  children [
    Shape {
      appearance PBRAppearance {
        baseColor 1 0 0
        roughness 0.4
      }
      geometry Box {
        size 0.1 0.001 5
      }
    }
    Shape {
      appearance PBRAppearance {
        baseColor 0 0 1
        roughness 0.4
      }
      geometry Box {
        size 5 0.001 0.1
      }
    }
  ]
}
Robot {
  children [
    SliderJoint {
      jointParameters JointParameters {
        position 0.10668372019704331
        axis 1 0 0
      }
      device [
        LinearMotor {
          name "carro_motor"
          maxForce 500
        }
        PositionSensor {
          name "carro_sensor"
        }
      ]
      endPoint Solid {
        translation 0.10668372019704331 0.075 0
        children [
          Shape {
            appearance PBRAppearance {
              baseColor 0.1 0.6 0.8
              roughness 0.3
            }
            geometry Box {
              size 0.3 0.05 0.2
            }
          }
          HingeJoint {
            jointParameters HingeJointParameters {
              position 0.17494876154451416
              axis 0 0 1
              anchor 0 0.025 0
            }
            device [
              PositionSensor {
                name "pendulo_sensor"
              }
              RotationalMotor {
                name "pendulo_motor"
              }
            ]
            endPoint Solid {
              translation 0 0.025 0
              rotation 0 0 1 0.17494876154451477
              children [
                Pose {
                  translation 0 0.6 0
                  children [
                    Shape {
                      appearance PBRAppearance {
                        baseColor 1 0.8 0
                        roughness 0.3
                      }
                      geometry Capsule {
                        height 1.2
                        radius 0.02
                      }
                    }
                  ]
                }
                Pose {
                  translation 0 1.15 0
                  children [
                    Shape {
                      appearance PBRAppearance {
                        baseColor 1 0 0
                        roughness 0.3
                      }
                      geometry Sphere {
                        radius 0.05
                      }
                    }
                  ]
                }
              ]
              name "pendulo"
              boundingObject Group {
                children [
                  Pose {
                    translation 0 0.6 0
                    children [
                      Capsule {
                        height 1.2
                        radius 0.02
                        subdivision 16
                      }
                    ]
                  }
                  Pose {
                    translation 0 1.15 0
                    children [
                      Sphere {
                        radius 0.05
                      }
                    ]
                  }
                ]
              }
              physics Physics {
                density -1
                mass 0.5
                centerOfMass [
                  0 0.6 0
                ]
              }
              linearVelocity -0.00015896309894193405 0.0010155120963662501 0.00027421233699764146
              angularVelocity 0.0004983373336828229 6.324071280756269e-05 -3.2295589636237834e-05
            }
          }
        ]
        name "carro"
        boundingObject Box {
          size 0.3 0.05 0.2
        }
        physics Physics {
          density -1
          mass 2
        }
        linearVelocity -0.00010064680565415075 0.0005082572949149835 -1.6543251281262885e-05
        angularVelocity 0.0002489586045146389 3.133887156356514e-05 1.9349642234209923e-06
      }
    }
  ]
  controller "pendulo_controller"
}
