#VRML_SIM R2025a utf8

EXTERNPROTO "https://raw.githubusercontent.com/cyberbotics/webots/R2025a/projects/objects/backgrounds/protos/TexturedBackground.proto"
EXTERNPROTO "https://raw.githubusercontent.com/cyberbotics/webots/R2025a/projects/objects/backgrounds/protos/TexturedBackgroundLight.proto"
EXTERNPROTO "https://raw.githubusercontent.com/cyberbotics/webots/R2025a/projects/objects/floors/protos/Floor.proto"
EXTERNPROTO "https://raw.githubusercontent.com/cyberbotics/webots/R2025a/projects/objects/floors/protos/RectangleArena.proto"

WorldInfo {
  basicTimeStep 16
}
Viewpoint {
  orientation -0.07555985702302945 -0.0625964383746015 -0.9951745544925643 1.762086451678722
  position -0.037254660989883254 3.8380674317215977 -0.049476849799256144
  description "Vista principal"
}
TexturedBackground {
}
TexturedBackgroundLight {
}
DirectionalLight {
  color 1 1 0.95
  direction -0.3 -1 -0.4
  intensity 0.9
}
Floor {
  appearance PBRAppearance {
    baseColorMap ImageTexture {
      url [
        "webots://projects/default/worlds/textures/wood.jpg"
      ]
    }
    roughness 0.5
    metalness 0
  }
}
RectangleArena {
  floorSize 5 5
  floorAppearance PBRAppearance {
    baseColorMap ImageTexture {
      url [
        "webots://projects/default/worlds/textures/rubber.jpg"
      ]
    }
  }
}
Solid {
  translation 0 0.01 0
  children [
    Shape {
      appearance PBRAppearance {
        baseColor 1 0 0
        roughness 0.4
      }
      geometry Box {
        size 0.1 0.001 5
      }
    }
    Shape {
      appearance PBRAppearance {
        baseColor 0 0 1
        roughness 0.4
      }
      geometry Box {
        size 5 0.001 0.1
      }
    }
  ]
}
Robot {
  children [
    SliderJoint {
      jointParameters JointParameters {
        position 0.10662480812308975
        axis 1 0 0
      }
      device [
        LinearMotor {
          name "carro_motor"
          maxForce 500
        }
        PositionSensor {
          name "carro_sensor"
        }
      ]
      endPoint Solid {
        translation 0.10662480812308975 0.075 0
        children [
          Shape {
            appearance PBRAppearance {
              baseColor 0.1 0.6 0.8
              roughness 0.3
            }
            geometry Box {
              size 0.3 0.05 0.2
            }
          }
          HingeJoint {
            jointParameters HingeJointParameters {
              position 0.16774675451257598
              axis 0 0 1
              anchor 0 0.025 0
            }
            device [
              PositionSensor {
                name "pendulo_sensor"
              }
              RotationalMotor {
                name "pendulo_motor"
              }
            ]
            endPoint Solid {
              translation 0 0.025 0
              rotation 0 0 1 0.1677467545125755
              children [
                Pose {
                  translation 0 0.6 0
                  children [
                    Shape {
                      appearance PBRAppearance {
                        baseColor 1 0.8 0
                        roughness 0.3
                      }
                      geometry Capsule {
                        height 1.2
                        radius 0.02
                      }
                    }
                  ]
                }
                Pose {
                  translation 0 1.15 0
                  children [
                    Shape {
                      appearance PBRAppearance {
                        baseColor 1 0 0
                        roughness 0.3
                      }
                      geometry Sphere {
                        radius 0.05
                      }
                    }
                  ]
                }
              ]
              name "pendulo"
              boundingObject Group {
                children [
                  Pose {
                    translation 0 0.6 0
                    children [
                      Capsule {
                        height 1.2
                        radius 0.02
                        subdivision 16
                      }
                    ]
                  }
                  Pose {
                    translation 0 1.15 0
                    children [
                      Sphere {
                        radius 0.05
                      }
                    ]
                  }
                ]
              }
              physics Physics {
                density -1
                mass 0.5
                centerOfMass [
                  0 0.6 0
                ]
              }
              linearVelocity -6.0307102044276915e-05 2.3570577171454944e-05 3.983910710587679e-07
              angularVelocity -1.5582140498823306e-08 7.729192211070192e-08 -0.0002351239850275098
            }
          }
        ]
        name "carro"
        boundingObject Box {
          size 0.3 0.05 0.2
        }
        physics Physics {
          density -1
          mass 2
        }
        linearVelocity -0.0001993804872701344 1.836524132288826e-08 4.088052106979258e-07
        angularVelocity 2.790483953143143e-07 -1.7001358042952114e-06 -6.858567219357253e-09
      }
    }
  ]
  controller "pendulo_controller"
}
